Workbook

Sheet Customer Names
A1: Customer ID | B1: name | D1: Customer ID | E1: First Name | F1: Last Name
A2: Id1 | B2: Hawks, Ms. Kelly | D2: Id1 | E2: Hawks | F2: Ms.kelly
A3: Id2 | B3: Lehner, Mr. Matthew D | D3: Id2 | E3: Lehner | F3: Mr.d
A4: Id3 | B4: Lu, Mr. Phil | D4: Id3 | E4: Lu | F4: Mr.phil
A5: Id4 | B5: Osborne, Ms. Kelsey | D5: Id4 | E5: Osborne | F5: Ms.kelsey
A6: Id5 | B6: Kadala, Ms. Kristyn | D6: Id5 | E6: Kadala | F6: Ms.kristyn
A7: Id6 | B7: Baker, Mr. Russell B. | D7: Id6 | E7: Baker | F7: Mr. Russell B.b.
A8: Id7 | B8: Macpherson, Mr. Scott | D8: Id7 | E8: Macpherson | F8: Mr.scott
A9: Id8 | B9: Hallman, Mr. Stephen | D9: Id8 | E9: Hallman | F9: Mr.stephen
A10: Id9 | B10: Moran, Mr. Patrick R. | D10: Id9 | E10: Moran | F10: Mr. Patrick R.r.
A11: Id10 | B11: Benner, Ms. Brooke N. | D11: Id10 | E11: Benner | F11: Ms. Brooke N.n.
A12: Id11 | B12: Fierro Vargas, Ms. Paola Andrea | D12: Id11 | E12: Fierro Vargas | F12: Ms.andrea
... A2336: Id2335 | B2336: German, Mr. Aaron K | D2336: Id2335 | E2336: German | F2336: Mr.k

Sheet Medical Examinations
A1: Customer ID | B1: BMI | C1: HBA1C | D1: Heart Issues | E1: Any Transplants | F1: Cancer history | G1: NumberOfMajorSurgeries | H1: smoker | L1: Customer ID | M1: BMI | N1: HBA1C | O1: Heart Issues | P1: Any Transplants | Q1: Cancer history | R1: NumberOfMajorSurgeries | S1: smoker | T1: Weight Status
A2: Id1 | B2: 47.41 | C2: 7.47 | D2: No | E2: No | F2: No | G2: No major surgery | H2: yes | L2: ID1 | M2: 47.41 | N2: 7.47 | O2: No | P2: No | Q2: No | R2: 0 | S2: yes | T2: Obesity
A3: Id2 | B3: 30.36 | C3: 5.77 | D3: No | E3: No | F3: No | G3: No major surgery | H3: yes | L3: ID10 | M3: 38.06 | N3: 10.79 | O3: No | P3: No | Q3: No | R3: 0 | S3: yes | T3: Obesity
A4: Id3 | B4: 34.485 | C4: 11.87 | D4: yes | E4: No | F4: No | G4: 2 | H4: yes | L4: ID100 | M4: 48.2 | N4: 4.84 | O4: No | P4: No | Q4: No | R4: 0 | S4: yes | T4: Obesity
A5: Id4 | B5: 38.095 | C5: 6.05 | D5: No | E5: No | F5: No | G5: No major surgery | H5: yes | L5: ID1000 | M5: 39.17 | N5: 4.15 | O5: No | P5: No | Q5: No | R5: 0 | S5: No | T5: Obesity
A6: Id5 | B6: 35.53 | C6: 5.45 | D6: No | E6: No | F6: No | G6: No major surgery | H6: yes | L6: ID1001 | M6: 26.41 | N6: 5.99 | O6: yes | P6: No | Q6: Yes | R6: 1 | S6: No | T6: Obesity
A7: Id6 | B7: 32.8 | C7: 6.59 | D7: No | E7: No | F7: No | G7: No major surgery | H7: yes | L7: ID1002 | M7: 30.63 | N7: 5.8 | O7: yes | P7: No | Q7: No | R7: 0 | S7: No | T7: Obesity
A8: Id7 | B8: 36.4 | C8: 6.07 | D8: No | E8: No | F8: No | G8: No major surgery | H8: yes | L8: ID1003 | M8: 31.73 | N8: 7.32 | O8: yes | P8: No | Q8: No | R8: 2 | S8: No | T8: Obesity
A9: Id8 | B9: 36.96 | C9: 7.93 | D9: No | E9: No | F9: No | G9: 3 | H9: yes | L9: ID1004 | M9: 30.7 | N9: 5.16 | O9: No | P9: No | Q9: No | R9: 2 | S9: No | T9: Obesity
A10: Id9 | B10: 41.14 | C10: 9.58 | D10: yes | E10: No | F10: Yes | G10: 1 | H10: yes | L10: ID1005 | M10: 25.935 | N10: 5.96 | O10: yes | P10: No | Q10: No | R10: 2 | S10: No | T10: Obesity
A11: Id10 | B11: 38.06 | C11: 10.79 | D11: No | E11: No | F11: No | G11: No major surgery | H11: yes | L11: ID1006 | M11: 35.9 | N11: 4.85 | O11: yes | P11: No | Q11: Yes | R11: 1 | S11: No | T11: Obesity
A12: Id11 | B12: 37.7 | C12: 5.96 | D12: yes | E12: No | F12: No | G12: 2 | H12: yes | L12: ID1007 | M12: 26.7 | N12: 5.09 | O12: yes | P12: No | Q12: Yes | R12: 1 | S12: No | T12: Obesity
A13: Id12 | B13: 42.13 | C13: 11.9 | D13: No | E13: No | F13: No | G13: No major surgery | H13: yes | L13: ID1008 | M13: 33.71 | N13: 4.94 | O13: No | P13: No | Q13: No | R13: 0 | S13: No | T13: Obesity
A14: Id13 | B14: 40.92 | C14: 8.41 | D14: No | E14: No | F14: No | G14: No major surgery | H14: yes | L14: ID1009 | M14: 41.91 | N14: 4.92 | O14: yes | P14: No | Q14: No | R14: 2 | S14: No | T14: Obesity
A15: Id14 | B15: 40.565 | C15: 7.02 | D15: No | E15: No | F15: No | G15: No major surgery | H15: yes | L15: ID101 | M15: 35.75 | N15: 8 | O15: yes | P15: No | Q15: No | R15: 0 | S15: yes | T15: Obesity
A16: Id15 | B16: 36.385 | C16: 7.59 | D16: yes | E16: No | F16: No | G16: 2 | H16: yes | L16: ID1010 | M16: 39.82 | N16: 6.05 | O16: yes | P16: No | Q16: No | R16: 2 | S16: No | T16: Obesity
A17: Id16 | B17: 39.9 | C17: 11.32 | D17: No | E17: No | F17: No | G17: No major surgery | H17: yes | L17: ID1011 | M17: 28.12 | N17: 4.67 | O17: No | P17: No | Q17: No | R17: 2 | S17: No | T17: Obesity
A18: Id17 | B18: 33.8 | C18: 7.67 | D18: No | E18: No | F18: No | G18: 3 | H18: yes | L18: ID1012 | M18: 26.98 | N18: 9.81 | O18: yes | P18: No | Q18: No | R18: 0 | S18: No | T18: Obesity
A19: Id18 | B19: 36.765 | C19: 7.29 | D19: yes | E19: No | F19: Yes | G19: 1 | H19: yes | L19: ID1013 | M19: 27.2 | N19: 6.06 | O19: yes | P19: No | Q19: No | R19: 2 | S19: No | T19: Obesity
A20: Id19 | B20: 36.955 | C20: 4.72 | D20: yes | E20: No | F20: No | G20: 1 | H20: yes | L20: ID1014 | M20: 25.3 | N20: 5.19 | O20: yes | P20: No | Q20: No | R20: 2 | S20: No | T20: Obesity
A21: Id20 | B21: 42.9 | C21: 11.41 | D21: No | E21: No | F21: No | G21: No major surgery | H21: yes | L21: ID1015 | M21: 30.25 | N21: 10.16 | O21: No | P21: No | Q21: No | R21: 0 | S21: No | T21: Obesity
A22: Id21 | B22: 36.3 | C22: 11.5 | D22: yes | E22: No | F22: No | G22: 2 | H22: yes | L22: ID1016 | M22: 54 | N22: 4.68 | O22: yes | P22: yes | Q22: No | R22: 2 | S22: No | T22: Obesity
A23: Id22 | B23: 32.2 | C23: 6.22 | D23: yes | E23: No | F23: No | G23: 2 | H23: yes | L23: ID1017 | M23: 51.86 | N23: 5.32 | O23: yes | P23: No | Q23: No | R23: 0 | S23: No | T23: Obesity
A24: Id23 | B24: 31.3 | C24: 11.38 | D24: No | E24: No | F24: No | G24: 3 | H24: yes | L24: ID1018 | M24: 31.39 | N24: 6.99 | O24: No | P24: No | Q24: No | R24: 0 | S24: No | T24: Obesity
A25: Id24 | B25: 41.8 | C25: 7.89 | D25: yes | E25: No | F25: No | G25: 2 | H25: yes | L25: ID1019 | M25: 39.97 | N25: 5.55 | O25: No | P25: No | Q25: No | R25: 0 | S25: No | T25: Obesity
A26: Id25 | B26: 35.09 | C26: 4.38 | D26: yes | E26: No | F26: No | G26: 2 | H26: yes | L26: ID102 | M26: 53.81 | N26: 8.77 | O26: yes | P26: No | Q26: No | R26: 0 | S26: yes | T26: Obesity
A27: Id26 | B27: 33.88 | C27: 7.01 | D27: No | E27: No | F27: No | G27: 3 | H27: yes | L27: ID1020 | M27: 41.23 | N27: 6.94 | O27: No | P27: No | Q27: No | R27: 0 | S27: No | T27: Obesity
A28: Id27 | B28: 30.875 | C28: 11.88 | D28: No | E28: No | F28: No | G28: No major surgery | H28: yes | L28: ID1021 | M28: 49.45 | N28: 4.2 | O28: yes | P28: No | Q28: No | R28: 0 | S28: No | T28: Obesity
A29: Id28 | B29: 36.86 | C29: 5.19 | D29: yes | E29: No | F29: Yes | G29: 1 | H29: yes | L29: ID1022 | M29: 41.04 | N29: 5.59 | O29: No | P29: No | Q29: No | R29: 0 | S29: No | T29: Obesity
A30: Id29 | B30: 35.86 | C30: 6.74 | D30: yes | E30: No | F30: No | G30: 2 | H30: yes | L30: ID1023 | M30: 27.93 | N30: 9.96 | O30: No | P30: No | Q30: No | R30: 0 | S30: No | T30: Obesity
A31: Id30 | B31: 37.05 | C31: 8.44 | D31: No | E31: No | F31: No | G31: No major surgery | H31: yes | L31: ID1024 | M31: 21.01 | N31: 7.37 | O31: No | P31: No | Q31: No | R31: 0 | S31: No | T31: Obesity
A32: Id31 | B32: 43.89 | C32: 8.71 | D32: No | E32: No | F32: No | G32: No major surgery | H32: yes | L32: ID1025 | M32: 52.37 | N32: 5.06 | O32: yes | P32: yes | Q32: No | R32: 2 | S32: No | T32: Obesity
A33: Id32 | B33: 42.35 | C33: 5.08 | D33: yes | E33: No | F33: No | G33: No major surgery | H33: yes | L33: ID1026 | M33: 40.37 | N33: 8.21 | O33: No | P33: No | Q33: No | R33: 0 | S33: No | T33: Obesity
A34: Id33 | B34: 31.35 | C34: 6.86 | D34: No | E34: No | F34: No | G34: No major surgery | H34: yes | L34: ID1027 | M34: 41.47 | N34: 10.34 | O34: No | P34: No | Q34: No | R34: 2 | S34: No | T34: Obesity
A35: Id34 | B35: 47.6 | C35: 5.95 | D35: yes | E35: No | F35: No | G35: No major surgery | H35: yes | L35: ID1028 | M35: 33.725 | N35: 5.51 | O35: yes | P35: No | Q35: No | R35: 2 | S35: No | T35: Obesity
A36: Id35 | B36: 46.2 | C36: 6.09 | D36: No | E36: No | F36: Yes | G36: 1 | H36: yes | L36: ID1029 | M36: 28.1 | N36: 11.2 | O36: No | P36: No | Q36: No | R36: 0 | S36: No | T36: Obesity
A37: Id36 | B37: 32.015 | C37: 11.75 | D37: No | E37: No | F37: No | G37: No major surgery | H37: yes | L37: ID103 | M37: 49.48 | N37: 4.96 | O37: No | P37: No | Q37: Yes | R37: 1 | S37: yes | T37: Obesity
A38: Id37 | B38: 40.565 | C38: 7.37 | D38: No | E38: No | F38: No | G38: No major surgery | H38: yes | L38: ID1030 | M38: 37.43 | N38: 4.35 | O38: yes | P38: No | Q38: Yes | R38: 1 | S38: No | T38: Obesity
A39: Id38 | B39: 32.45 | C39: 11.91 | D39: No | E39: No | F39: No | G39: No major surgery | H39: yes | L39: ID1031 | M39: 23.7 | N39: 10.45 | O39: No | P39: No | Q39: No | R39: 0 | S39: No | T39: Obesity
A40: Id39 | B40: 34.96 | C40: 6.52 | D40: No | E40: No | F40: No | G40: No major surgery | H40: yes | L40: ID1032 | M40: 24.795 | N40: 4.07 | O40: yes | P40: No | Q40: Yes | R40: 1 | S40: No | T40: Obesity
...

Sheet Hospitalisation Details
A1: Customer ID | B1: year | C1: month | D1: date | E1: children | F1: charges | G1: Hospital tier | H1: City tier | I1: State ID | K1: Customer ID | L1: Date Of Birth | M1: children | N1: charges | O1: Hospital tier | P1: City tier | Q1: State ID | R1: Age
A2: Id2335 | B2: 1992 | C2: Jul | D2: 9 | E2: 0 | F2: 563.84 | G2: tier - 2 | H2: tier - 3 | I2: R1013 | K2: Id2335 | L2: 33794 | M2: 0 | N2: 564 | O2: tier - 2 | P2: tier - 3 | Q2: R1013 | R2: 30
A3: Id2334 | B3: 1992 | C3: Nov | D3: 30 | E3: 0 | F3: 570.62 | G3: tier - 2 | H3: tier - 1 | I3: R1013 | K3: Id2334 | L3: 33938 | M3: 0 | N3: 571 | O3: tier - 2 | P3: tier - 1 | Q3: R1013 | R3: 30
A4: Id2333 | B4: 1993 | C4: Jun | D4: 30 | E4: 0 | F4: 600 | G4: tier - 2 | H4: tier - 1 | I4: R1013 | K4: Id2333 | L4: 34150 | M4: 0 | N4: 600 | O4: tier - 2 | P4: tier - 1 | Q4: R1013 | R4: 29
A5: Id2332 | B5: 1992 | C5: Sep | D5: 13 | E5: 0 | F5: 604.54 | G5: tier - 3 | H5: tier - 3 | I5: R1013 | K5: Id2332 | L5: 33860 | M5: 0 | N5: 605 | O5: tier - 3 | P5: tier - 3 | Q5: R1013 | R5: 30
A6: Id2331 | B6: 1998 | C6: Jul | D6: 27 | E6: 0 | F6: 637.26 | G6: tier - 3 | H6: tier - 3 | I6: R1013 | K6: Id2331 | L6: 36003 | M6: 0 | N6: 637 | O6: tier - 3 | P6: tier - 3 | Q6: R1013 | R6: 24
A7: Id2330 | B7: 2001 | C7: Nov | D7: 20 | E7: 0 | F7: 646.14 | G7: tier - 3 | H7: tier - 3 | I7: R1012 | K7: Id2330 | L7: 37215 | M7: 0 | N7: 646 | O7: tier - 3 | P7: tier - 3 | Q7: R1012 | R7: 21
A8: Id2329 | B8: 1993 | C8: Jun | D8: 1 | E8: 0 | F8: 650 | G8: tier - 3 | H8: tier - 3 | I8: R1013 | K8: Id2329 | L8: 34121 | M8: 0 | N8: 650 | O8: tier - 3 | P8: tier - 3 | Q8: R1013 | R8: 30
A9: Id2328 | B9: 1995 | C9: Jul | D9: 4 | E9: 0 | F9: 650 | G9: tier - 3 | H9: tier - 3 | I9: R1013 | K9: Id2328 | L9: 34884 | M9: 0 | N9: 650 | O9: tier - 3 | P9: tier - 3 | Q9: R1013 | R9: 27
A10: Id2327 | B10: 2002 | C10: Nov | D10: 29 | E10: 0 | F10: 668 | G10: tier - 3 | H10: tier - 2 | I10: R1012 | K10: Id2327 | L10: 37589 | M10: 0 | N10: 668 | O10: tier - 3 | P10: tier - 2 | Q10: R1012 | R10: 20
A11: Id2326 | B11: 1997 | C11: Nov | D11: 9 | E11: 0 | F11: 670 | G11: tier - 3 | H11: tier - 3 | I11: R1013 | K11: Id2326 | L11: 35743 | M11: 0 | N11: 670 | O11: tier - 3 | P11: tier - 3 | Q11: R1013 | R11: 25
A12: Id2325 | B12: 2001 | C12: Sep | D12: 12 | E12: 0 | F12: 687.54 | G12: tier - 3 | H12: tier - 2 | I12: R1013 | K12: Id2325 | L12: 37146 | M12: 0 | N12: 688 | O12: tier - 3 | P12: tier - 2 | Q12: R1013 | R12: 21
A13: Id2324 | B13: 1999 | C13: Dec | D13: 26 | E13: 0 | F13: 700 | G13: ? | H13: tier - 3 | I13: R1013 | K13: Id2324 | L13: 36520 | M13: 0 | N13: 700 | O13: tier - 3 | P13: tier - 3 | Q13: R1013 | R13: 23
... A1050: Id1290 | B1050: 1977 | C1050: Jul | D1050: 26 | E1050: 2 | F1050: 8527.53 | G1050: tier - 2 | H1050: tier - 2 | I1050: R1013 | K1050: Id1290 | L1050: 28332 | M1050: 2 | N1050: 8528 | O1050: tier - 2 | P1050: tier - 2 | Q1050: R1013 | R1050: 45
A1051: Id1289 | B1051: ? | C1051: Jul | D1051: 24 | E1051: 0 | F1051: 8534.67 | G1051: tier - 2 | H1051: tier - 3 | I1051: R1024 | K1051: Id1289 | L1051: #VALUE! | M1051: 0 | N1051: 8535 | O1051: tier - 2 | P1051: tier - 3 | Q1051: R1024 | R1051: #VALUE!
A1052: Id1288 | B1052: 1981 | C1052: Dec | D1052: 27 | E1052: 3 | F1052: 8538.29 | G1052: tier - 2 | H1052: tier - 3 | I1052: R1024 | K1052: Id1288 | L1052: 29947 | M1052: 3 | N1052: 8538 | O1052: tier - 2 | P1052: tier - 3 | Q1052: R1024 | R1052: 41
A1053: Id1287 | B1053: 1975 | C1053: Nov | D1053: 6 | E1053: 1 | F1053: 8539.67 | G1053: tier - 2 | H1053: tier - 3 | I1053: R1011 | K1053: Id1287 | L1053: 27704 | M1053: 1 | N1053: 8540 | O1053: tier - 2 | P1053: tier - 3 | Q1053: R1011 | R1053: 47
A1054: Id1286 | B1054: ? | C1054: Dec | D1054: 12 | E1054: 1 | F1054: 8547.69 | G1054: tier - 2 | H1054: tier - 1 | I1054: R1013 | K1054: Id1286 | L1054: #VALUE! | M1054: 1 | N1054: 8548 | O1054: tier - 2 | P1054: tier - 1 | Q1054: R1013 | R1054: #VALUE!
A1055: Id1285 | B1055: 1975 | C1055: Aug | D1055: 6 | E1055: 1 | F1055: 8551.35 | G1055: tier - 2 | H1055: tier - 2 | I1055: R1011 | K1055: Id1285 | L1055: 27612 | M1055: 1 | N1055: 8551 | O1055: tier - 2 | P1055: tier - 2 | Q1055: R1011 | R1055: 47
A1056: Id1284 | B1056: 1975 | C1056: Aug | D1056: 21 | E1056: 1 | F1056: 8556.91 | G1056: tier - 2 | H1056: tier - 1 | I1056: R1011 | K1056: Id1284 | L1056: 27627 | M1056: 1 | N1056: 8557 | O1056: tier - 2 | P1056: tier - 1 | Q1056: R1011 | R1056: 47
A1057: Id1283 | B1057: 1988 | C1057: Sep | D1057: 21 | E1057: 3 | F1057: 8567.25 | G1057: tier - 2 | H1057: tier - 1 | I1057: R1012 | K1057: Id1283 | L1057: 32407 | M1057: 3 | N1057: 8567 | O1057: tier - 2 | P1057: tier - 1 | Q1057: R1012 | R1057: 34
A1058: Id1282 | B1058: 1975 | C1058: Sep | D1058: 26 | E1058: 1 | F1058: 8569.86 | G1058: tier - 2 | H1058: tier - 3 | I1058: R1013 | K1058: Id1282 | L1058: 27663 | M1058: 1 | N1058: 8570 | O1058: tier - 2 | P1058: tier - 3 | Q1058: R1013 | R1058: 47
A1059: Id1281 | B1059: 1982 | C1059: Dec | D1059: 6 | E1059: 3 | F1059: 8572.04 | G1059: tier - 2 | H1059: tier - 2 | I1059: R1021 | K1059: Id1281 | L1059: 30291 | M1059: 3 | N1059: 8572 | O1059: tier - 2 | P1059: tier - 2 | Q1059: R1021 | R1059: 40
A1060: Id1280 | B1060: 1987 | C1060: Nov | D1060: 11 | E1060: 3 | F1060: 8573.3 | G1060: tier - 2 | H1060: tier - 2 | I1060: R1021 | K1060: Id1280 | L1060: 32092 | M1060: 3 | N1060: 8573 | O1060: tier - 2 | P1060: tier - 2 | Q1060: R1021 | R1060: 35
A1061: Id1279 | B1061: 1983 | C1061: Dec | D1061: 30 | E1061: 5 | F1061: 8582.3 | G1061: tier - 2 | H1061: tier - 1 | I1061: R1013 | K1061: Id1279 | L1061: 30680 | M1061: 5 | N1061: 8582 | O1061: tier - 2 | P1061: tier - 1 | Q1061: R1013 | R1061: 39
A1062: Id1278 | B1062: 1983 | C1062: Jul | D1062: 25 | E1062: 5 | F1062: 8596.83 | G1062: tier - 2 | H1062: tier - 3 | I1062: R1013 | K1062: Id1278 | L1062: 30522 | M1062: 5 | N1062: 8597 | O1062: tier - 2 | P1062: tier - 3 | Q1062: R1013 | R1062: 39
A1063: Id1277 | B1063: 1973 | C1063: Jul | D1063: 11 | E1063: 0 | F1063: 8601.33 | G1063: tier - 2 | H1063: tier - 1 | I1063: R1013 | K1063: Id1277 | L1063: 26856 | M1063: 0 | N1063: 8601 | O1063: tier - 2 | P1063: tier - 1 | Q1063: R1013 | R1063: 49
A1064: Id1276 | B1064: 1977 | C1064: Sep | D1064: 24 | E1064: 2 | F1064: 8603.82 | G1064: tier - 2 | H1064: tier - 1 | I1064: R1019 | K1064: Id1276 | L1064: 28392 | M1064: 2 | N1064: 8604 | O1064: tier - 2 | P1064: tier - 1 | Q1064: R1019 | R1064: 45
A1065: Id1275 | B1065: 1977 | C1065: Nov | D1065: 12 | E1065: 2 | F1065: 8604.48 | G1065: tier - 3 | H1065: tier - 2 | I1065: R1016 | K1065: Id1275 | L1065: 28441 | M1065: 2 | N1065: 8604 | O1065: tier - 3 | P1065: tier - 2 | Q1065: R1016 | R1065: 45
A1066: Id1274 | B1066: 1977 | C1066: Oct | D1066: 15 | E1066: 3 | F1066: 8605.36 | G1066: tier - 2 | H1066: tier - 2 | I1066: R1013 | K1066: Id1274 | L1066: 28413 | M1066: 3 | N1066: 8605 | O1066: tier - 2 | P1066: tier - 2 | Q1066: R1013 | R1066: 45
... A2344: Id1 | B2344: 1968 | C2344: Oct | D2344: 12 | E2344: 0 | F2344: 63770.43 | G2344: tier - 1 | H2344: tier - 3 | I2344: R1013 | K2344: Id1 | L2344: 25123 | M2344: 0 | N2344: 63770 | O2344: tier - 1 | P2344: tier - 3 | Q2344: R1013 | R2344: 54

Sheet  Healthcare.
A1: Customer ID | B1: First Name | C1: BMI | D1: HBA1C | E1: Heart Issues | F1: Any Transplants | G1: Cancer history | H1: NumberOfMajorSurgeries | I1: smoker | J1: Weight Status | K1: children | L1: Date Of Birth | M1: charges | N1: Hospital tier | O1: City tier | P1: State ID | Q1: Age | R1: Total customers count | S1: 2335
A2: Id1 | B2: Hawks | C2: 47.41 | D2: 7.47 | E2: No | F2: No | G2: No | H2: 0 | I2: yes | J2: Obesity | K2: 0 | L2: 25123 | M2: 63770.43 | N2: tier - 1 | O2: tier - 3 | P2: R1013 | Q2: 54 | R2: Total hospitalisation count | S2: =SUM(M2:M2336) -> 31592359
A3: Id2 | B3: Lehner | C3: 30.36 | D3: 5.77 | E3: No | F3: No | G3: No | H3: 0 | I3: yes | J3: Obesity | K3: 0 | L3: 28284 | M3: 62592.87 | N3: tier - 2 | O3: tier - 3 | P3: R1013 | Q3: 45 | R3: Average HBA1C | S3: =AVERAGE(D1:D2335) -> 6.5798843
A4: Id3 | B4: Lu | C4: 34.485 | D4: 11.87 | E4: yes | F4: No | G4: No | H4: 2 | I4: yes | J4: Obesity | K4: 3 | L4: 25822 | M4: 60021.4 | N4: tier - 1 | O4: tier - 1 | P4: R1012 | Q4: 52 | R4: Average BMI | S4: =AVERAGE(C1:C2335) -> 30.978387
A5: Id4 | B5: Osborne | C5: 38.095 | D5: 6.05 | E5: No | F5: No | G5: No | H5: 0 | I5: yes | J5: Obesity | K5: 1 | L5: 33395 | M5: 58571.07 | N5: tier - 1 | O5: tier - 3 | P5: R1024 | Q5: 32
A6: Id5 | B6: Kadala | C6: 35.53 | D6: 5.45 | E6: No | F6: No | G6: No | H6: 0 | I6: yes | J6: Obesity | K6: 0 | L6: 32678 | M6: 55135.4 | N6: tier - 1 | O6: tier - 2 | P6: R1012 | Q6: 33
A7: Id6 | B7: Baker | C7: 32.8 | D7: 6.59 | E7: No | F7: No | G7: No | H7: 0 | I7: yes | J7: Obesity | K7: 0 | L7: 22862 | M7: 52590.83 | N7: tier - 1 | O7: tier - 3 | P7: R1011 | Q7: 60
A8: Id7 | B8: Macpherson | C8: 36.4 | D8: 6.07 | E8: No | F8: No | G8: No | H8: 0 | I8: yes | J8: Obesity | K8: 1 | L8: 34634 | M8: 51194.56 | N8: tier - 1 | O8: tier - 3 | P8: R1011 | Q8: 28
A9: Id8 | B9: Hallman | C9: 36.96 | D9: 7.93 | E9: No | F9: No | G9: No | H9: 3 | I9: yes | J9: Obesity | K9: 2 | L9: 21363 | M9: 49577.66 | N9: tier - 2 | O9: tier - 2 | P9: R1013 | Q9: 64
A10: Id9 | B10: Moran | C10: 41.14 | D10: 9.58 | E10: yes | F10: No | G10: Yes | H10: 1 | I10: yes | J10: Obesity | K10: 1 | L10: 23258 | M10: 48970.25 | N10: tier - 1 | O10: tier - 2 | P10: R1013 | Q10: 59
A11: Id10 | B11: Benner | C11: 38.06 | D11: 10.79 | E11: No | F11: No | G11: No | H11: 0 | I11: yes | J11: Obesity | K11: 0 | L11: 28853 | M11: 48885.14 | N11: tier - 1 | O11: tier - 2 | P11: R1013 | Q11: 44
A12: Id11 | B12: Fierro Vargas | C12: 37.7 | D12: 5.96 | E12: yes | F12: No | G12: No | H12: 2 | I12: yes | J12: Obesity | K12: 0 | L12: 21753 | M12: 48824.45 | N12: tier - 2 | O12: tier - 1 | P12: R1011 | Q12: 63
A13: Id12 | B13: Franz | C13: 42.13 | D13: 11.9 | E13: No | F13: No | G13: No | H13: 0 | I13: yes | J13: Obesity | K13: 1 | L13: 24042 | M13: 48675.52 | N13: tier - 1 | O13: tier - 2 | P13: R1013 | Q13: 57
A14: Id13 | B14: Foster | C14: 40.92 | D14: 8.41 | E14: No | F14: No | G14: No | H14: 0 | I14: yes | J14: Obesity | K14: 0 | L14: 22930 | M14: 48673.56 | N14: tier - 1 | O14: tier - 2 | P14: R1013 | Q14: 60
A15: Id14 | B15: Tenorio | C15: 40.565 | D15: 7.02 | E15: No | F15: No | G15: No | H15: 0 | I15: yes | J15: Obesity | K15: 3 | L15: 25173 | M15: 48549.18 | N15: tier - 1 | O15: tier - 3 | P15: R1016 | Q15: 54
A16: Id15 | B16: Rios | C16: 36.385 | D16: 7.59 | E16: yes | F16: No | G16: No | H16: 2 | I16: yes | J16: Obesity | K16: 1 | L16: 22636 | M16: 48517.56 | N16: tier - 1 | O16: tier - 3 | P16: R1024 | Q16: 61
... A1286: Id1285 | B1286: Bokun | C1286: 32 | D1286: 7.85 | E1286: yes | F1286: No | G1286: No | H1286: 1 | I1286: No | J1286: Obesity | K1286: 1 | L1286: 27612 | M1286: 8551.35 | N1286: tier - 2 | O1286: tier - 2 | P1286: R1011 | Q1286: 47
A1287: Id1286 | B1287: Ainsley | C1287: 29.37 | D1287: 8.01 | E1287: yes | F1287: No | G1287: No | H1287: 1 | I1287: No | J1287: Overweight | K1287: 1 | L1287: Unknow | M1287: 8547.69 | N1287: tier - 2 | O1287: tier - 1 | P1287: R1013 | Q1287: Unknow
A1288: Id1287 | B1288: Foster | C1288: 23.6 | D1288: 7.4 | E1288: yes | F1288: No | G1288: No | H1288: 1 | I1288: No | J1288: Normal Weight | K1288: 1 | L1288: 27704 | M1288: 8539.67 | N1288: tier - 2 | O1288: tier - 3 | P1288: R1011 | Q1288: 47
A1289: Id1288 | B1289: Overpeck | C1289: 33.155 | D1289: 8.38 | E1289: yes | F1289: No | G1289: No | H1289: 0 | I1289: No | J1289: Obesity | K1289: 3 | L1289: 29947 | M1289: 8538.29 | N1289: tier - 2 | O1289: tier - 3 | P1289: R1024 | Q1289: 41
A1290: Id1289 | B1290: Levine | C1290: 24.32 | D1290: 11.56 | E1290: yes | F1290: No | G1290: No | H1290: 1 | I1290: No | J1290: Normal Weight | K1290: 0 | L1290: Unknow | M1290: 8534.67 | N1290: tier - 2 | O1290: tier - 3 | P1290: R1024 | Q1290: Unknow
A1291: Id1290 | B1291: Jean | C1291: 36.3 | D1291: 4.61 | E1291: No | F1291: No | G1291: No | H1291: 0 | I1291: No | J1291: Obesity | K1291: 2 | L1291: 28332 | M1291: 8527.53 | N1291: tier - 2 | O1291: tier - 2 | P1291: R1013 | Q1291: 45
A1292: Id1291 | B1292: Wild | C1292: 34.4 | D1292: 4.95 | E1292: No | F1292: No | G1292: Yes | H1292: 1 | I1292: No | J1292: Obesity | K1292: 3 | L1292: 29080 | M1292: 8522 | N1292: tier - 2 | O1292: tier - 2 | P1292: R1011 | Q1292: 43
A1293: Id1292 | B1293: Tabor | C1293: 30.9 | D1293: 5.04 | E1293: No | F1293: No | G1293: No | H1293: 0 | I1293: No | J1293: Obesity | K1293: 2 | L1293: 28488 | M1293: 8520.03 | N1293: tier - 2 | O1293: tier - 3 | P1293: R1011 | Q1293: 45
A1294: Id1293 | B1294: Steffen | C1294: 28.6 | D1294: 5.42 | E1294: No | F1294: No | G1294: No | H1294: 0 | I1294: No | J1294: Overweight | K1294: 2 | L1294: 28297 | M1294: 8516.83 | N1294: tier - 2 | O1294: tier - 1 | P1294: R1013 | Q1294: 45
A1295: Id1294 | B1295: Tadich | C1295: 27.83 | D1295: 5.39 | E1295: No | F1295: No | G1295: No | H1295: 0 | I1295: No | J1295: Overweight | K1295: 2 | L1295: 28485 | M1295: 8515.76 | N1295: tier - 2 | O1295: tier - 2 | P1295: R1013 | Q1295: 45
A1296: Id1295 | B1296: Christenson | C1296: 39.64 | D1296: 6 | E1296: No | F1296: No | G1296: Yes | H1296: 1 | I1296: No | J1296: Obesity | K1296: 0 | L1296: 34283 | M1296: 8471.65 | N1296: tier - 2 | O1296: tier - 1 | P1296: R1012 | Q1296: 29
A1297: Id1296 | B1297: Shell | C1297: 38.48 | D1297: 6.02 | E1297: No | F1297: No | G1297: No | H1297: 1 | I1297: No | J1297: Obesity | K1297: 0 | L1297: 33856 | M1297: 8466.35 | N1297: tier - 2 | O1297: tier - 2 | P1297: R1012 | Q1297: 30
A1298: Id1297 | B1298: Rao | C1298: 36.2 | D1298: 4.62 | E1298: No | F1298: No | G1298: No | H1298: 2 | I1298: No | J1298: Obesity | K1298: 0 | L1298: 26659 | M1298: 8457.82 | N1298: tier - 2 | O1298: tier - 3 | P1298: R1011 | Q1298: 50
A1299: Id1298 | B1299: Myers | C1299: 27.13 | D1299: 5.59 | E1299: No | F1299: No | G1299: No | H1299: 1 | I1299: No | J1299: Overweight | K1299: 3 | L1299: 30852 | M1299: 8450.82 | N1299: tier - 2 | O1299: tier - 2 | P1299: R1025 | Q1299: 38
A1300: Id1299 | B1300: McLean | C1300: 20.75 | D1300: 5.18 | E1300: yes | F1300: No | G1300: No | H1300: 2 | I1300: No | J1300: Normal Weight | K1300: 0 | L1300: 24270 | M1300: 8448.66 | N1300: tier - 3 | O1300: tier - 1 | P1300: R1013 | Q1300: 56
A1301: Id1300 | B1301: Gomez | C1301: 26.6 | D1301: 6.29 | E1301: No | F1301: No | G1301: No | H1301: 2 | I1301: No | J1301: Overweight | K1301: 0 | L1301: 26546 | M1301: 8444.47 | N1301: tier - 3 | O1301: tier - 1 | P1301: R1011 | Q1301: 50
A1302: Id1301 | B1302: Hemingway | C1302: 25.3 | D1302: 4.49 | E1302: No | F1302: No | G1302: No | H1302: 2 | I1302: No | J1302: Overweight | K1302: 0 | L1302: 26551 | M1302: 8442.67 | N1302: tier - 2 | O1302: tier - 3 | P1302: R1013 | Q1302: 50
... A2336: Id2335 | B2336: German | C2336: 17.58 | D2336: 4.51 | E2336: No | F2336: No | G2336: No | H2336: 1 | I2336: No | J2336: Underweight | K2336: 0 | L2336: 33794 | M2336: 563.84 | N2336: tier - 2 | O2336: tier - 3 | P2336: R1013 | Q2336: 30
A2339: =COUNTA(A2:A2336) -> 2335 | C2339: =AVERAGE(C2:C2336) -> 30.972649 | D2339: =AVERAGE(D2:D2336) -> 6.5789979 | M2339: =SUM(M2:M2336) -> 31592359

Sheet Manual Dashboard
A1: Dashboard

Sheet sheet
A3: Row Labels | B3: Count of smoker
A4: No | B4: 1944
A5: Yes | B5: 391
A6: Grand Total | B6: 2335
B16: Column Labels
B17: Normal Weight | C17: Obesity | D17: Overweight | E17: Underweight | F17: Grand Total
A18: Sum of charges | B18: 7553531 | C18: 12800928 | D18: 6844972 | E18: 4116014 | F18: 31315445
D2324: 5.94
C2337: =AVERAGE(C2:C2336) -> 12800928 | D2337: =AVERAGE(D2:D2336) -> 3422489

Sheet Cancer Analysis
A1: Status | B1: Smokers | C1: Non-Smokers
A2: Cancer History: Yes | B2: =COUNTIFS(' Healthcare.'!I:I, "yes", ' Healthcare.'!G:G, "Yes") -> 84 | C2: =COUNTIFS(' Healthcare.'!I:I, "No", ' Healthcare.'!G:G, "Yes") -> 307
A3: Cancer History: No | B3: =COUNTIFS(' Healthcare.'!I:I, "yes", ' Healthcare.'!G:G, "No") -> 404 | C3: =COUNTIFS(' Healthcare.'!I:I, "No", ' Healthcare.'!G:G, "No") -> 1540

Sheet Weight Analysis
A1: Customer ID | B1: BMI | C1: Charges | D1: Weight Status | F1: Weight Status | G1: Total Charges
A2: Id1 | B2: 47.41 | C2: =_xlfn.XLOOKUP(A2, 'Hospitalisation Details'!A:A, 'Hospitalisation Details'!F:F) -> 63770.43 | D2: =IF(B2<18.5, "Underweight", IF(B2<25, "Normal", IF(B2<30, "Overweight", "Obesity"))) -> Obesity | F2: Underweight | G2: =SUMIF(D:D, F2, C:C) -> 1214279.9
A3: Id2 | B3: 30.36 | C3: =_xlfn.XLOOKUP(A3, 'Hospitalisation Details'!A:A, 'Hospitalisation Details'!F:F) -> 62592.87 | D3: =IF(B3<18.5, "Underweight", IF(B3<25, "Normal", IF(B3<30, "Overweight", "Obesity"))) -> Obesity | F3: Normal | G3: =SUMIF(D:D, F3, C:C) -> 4305290.1
A4: Id3 | B4: 34.485 | C4: =_xlfn.XLOOKUP(A4, 'Hospitalisation Details'!A:A, 'Hospitalisation Details'!F:F) -> 60021.4 | D4: =IF(B4<18.5, "Underweight", IF(B4<25, "Normal", IF(B4<30, "Overweight", "Obesity"))) -> Obesity | F4: Overweight | G4: =SUMIF(D:D, F4, C:C) -> 5729141.8
A5: Id4 | B5: 38.095 | C5: =_xlfn.XLOOKUP(A5, 'Hospitalisation Details'!A:A, 'Hospitalisation Details'!F:F) -> 58571.07 | D5: =IF(B5<18.5, "Underweight", IF(B5<25, "Normal", IF(B5<30, "Overweight", "Obesity"))) -> Obesity | F5: Obesity | G5: =SUMIF(D:D, F5, C:C) -> 20343647
A6: Id5 | B6: 35.53 | C6: =_xlfn.XLOOKUP(A6, 'Hospitalisation Details'!A:A, 'Hospitalisation Details'!F:F) -> 55135.4 | D6: =IF(B6<18.5, "Underweight", IF(B6<25, "Normal", IF(B6<30, "Overweight", "Obesity"))) -> Obesity
A7: Id6 | B7: 32.8 | C7: =_xlfn.XLOOKUP(A7, 'Hospitalisation Details'!A:A, 'Hospitalisation Details'!F:F) -> 52590.83 | D7: =IF(B7<18.5, "Underweight", IF(B7<25, "Normal", IF(B7<30, "Overweight", "Obesity"))) -> Obesity
A8: Id7 | B8: 36.4 | C8: =_xlfn.XLOOKUP(A8, 'Hospitalisation Details'!A:A, 'Hospitalisation Details'!F:F) -> 51194.56 | D8: =IF(B8<18.5, "Underweight", IF(B8<25, "Normal", IF(B8<30, "Overweight", "Obesity"))) -> Obesity
A9: Id8 | B9: 36.96 | C9: =_xlfn.XLOOKUP(A9, 'Hospitalisation Details'!A:A, 'Hospitalisation Details'!F:F) -> 49577.66 | D9: =IF(B9<18.5, "Underweight", IF(B9<25, "Normal", IF(B9<30, "Overweight", "Obesity"))) -> Obesity
A10: Id9 | B10: 41.14 | C10: =_xlfn.XLOOKUP(A10, 'Hospitalisation Details'!A:A, 'Hospitalisation Details'!F:F) -> 48970.25 | D10: =IF(B10<18.5, "Underweight", IF(B10<25, "Normal", IF(B10<30, "Overweight", "Obesity"))) -> Obesity
A11: Id10 | B11: 38.06 | C11: =_xlfn.XLOOKUP(A11, 'Hospitalisation Details'!A:A, 'Hospitalisation Details'!F:F) -> 48885.14 | D11: =IF(B11<18.5, "Underweight", IF(B11<25, "Normal", IF(B11<30, "Overweight", "Obesity"))) -> Obesity
A12: Id11 | B12: 37.7 | C12: =_xlfn.XLOOKUP(A12, 'Hospitalisation Details'!A:A, 'Hospitalisation Details'!F:F) -> 48824.45 | D12: =IF(B12<18.5, "Underweight", IF(B12<25, "Normal", IF(B12<30, "Overweight", "Obesity"))) -> Obesity
A13: Id12 | B13: 42.13 | C13: =_xlfn.XLOOKUP(A13, 'Hospitalisation Details'!A:A, 'Hospitalisation Details'!F:F) -> 48675.52 | D13: =IF(B13<18.5, "Underweight", IF(B13<25, "Normal", IF(B13<30, "Overweight", "Obesity"))) -> Obesity
A14: Id13 | B14: 40.92 | C14: =_xlfn.XLOOKUP(A14, 'Hospitalisation Details'!A:A, 'Hospitalisation Details'!F:F) -> 48673.56 | D14: =IF(B14<18.5, "Underweight", IF(B14<25, "Normal", IF(B14<30, "Overweight", "Obesity"))) -> Obesity
A15: Id14 | B15: 40.565 | C15: =_xlfn.XLOOKUP(A15, 'Hospitalisation Details'!A:A, 'Hospitalisation Details'!F:F) -> 48549.18 | D15: =IF(B15<18.5, "Underweight", IF(B15<25, "Normal", IF(B15<30, "Overweight", "Obesity"))) -> Obesity
A16: Id15 | B16: 36.385 | C16: =_xlfn.XLOOKUP(A16, 'Hospitalisation Details'!A:A, 'Hospitalisation Details'!F:F) -> 48517.56 | D16: =IF(B16<18.5, "Underweight", IF(B16<25, "Normal", IF(B16<30, "Overweight", "Obesity"))) -> Obesity
A17: Id16 | B17: 39.9 | C17: =_xlfn.XLOOKUP(A17, 'Hospitalisation Details'!A:A, 'Hospitalisation Details'!F:F) -> 48173.36 | D17: =IF(B17<18.5, "Underweight", IF(B17<25, "Normal", IF(B17<30, "Overweight", "Obesity"))) -> Obesity
... A2336: Id2335 | B2336: 17.58 | C2336: =_xlfn.XLOOKUP(A2336, 'Hospitalisation Details'!A:A, 'Hospitalisation Details'!F:F) -> 563.84 | D2336: =IF(B2336<18.5, "Underweight", IF(B2336<25, "Normal", IF(B2336<30, "Overweight", "Obesity"))) -> Underweight

Sheet Analysis_Data
A1: Row Labels | B1: Count of Smoker | D1: Row Labels | E1: Count of Hospital Tier | G1: Row Labels | H1: Count of City Tier
A2: ? | B2: 2 | D2: ? | E2: 1 | G2: ? | H2: 1
A3: No | B3: 1845 | D3: tier - 1 | E3: 304 | G3: tier - 1 | H3: 732
A4: yes | B4: 488 | D4: tier - 2 | E4: 1337 | G4: tier - 2 | H4: 808
A5: (blank) | D5: tier - 3 | E5: 693 | G5: tier - 3 | H5: 794
A6: Grand Total | B6: 2335 | D6: (blank) | G6: (blank)
D7: Grand Total | E7: 2335 | G7: Grand Total | H7: 2335
O11: Column Labels
O12: No | P12: yes | Q12: Grand Total
B13: Row Labels | C13: Sum of charges | N13: Sum of charges | O13: 18367761 | P13: 13224598 | Q13: 31592359
B14: 18 | C14: 621463.29
B15: 19 | C15: 832238.07
B16: 20 | C16: 429864
B17: 21 | C17: 224224.76
B18: 22 | C18: 509924.09
B19: 23 | C19: 554646.68
B20: 24 | C20: 449216.28
B21: 25 | C21: 523538.56
B22: 26 | C22: 260505.82
B23: 27 | C23: 604158.33
B24: 28 | C24: 536487.34
B25: 29 | C25: 505306.73
... B61: 65 | C61: 29330.98
B62: Unknow | C62: 17082.36
B63: Grand Total | C63: 31592359
